Workbook

Sheet SUMMARY
A1: SUMMARY OF 2025 WATER QUALITY ANALYSIS
A2: Regular Monitoring | B2: Water Classification for WQG | C2: Annual Average
C3: DO | D3: BOD | E3: TSS | F3: pH | G3: TEMP | H3: COLOR | I3: FECAL COLIFORM | J3: NITRATES | K3: PHOSPHATES | L3: CHLORIDES
A4: Priority Water Bodies
A5: Bocaue River | B5: C | C5: ='BOCAUE RIVER'!AC29 -> 3.5875 | D5: ='BOCAUE RIVER'!AD29 -> 7.9444444 | E5: ='BOCAUE RIVER'!AE29 -> 26.972222 | F5: ='BOCAUE RIVER'!AF29 -> 7.3097222 | G5: ='BOCAUE RIVER'!AG29 -> 28.405556 | H5: ='BOCAUE RIVER'!AH29 -> 21.805556 | I5: ='BOCAUE RIVER'!AI29 -> 210340.14 | J5: ='BOCAUE RIVER'!AJ29 -> 0.9121 | ... L5: ='BOCAUE RIVER'!AL29 -> 118.86111
A6: Santa Maria River | B6: C | C6: ='STA. MARIA RIVER'!AC29 -> 3.2158333 | D6: ='STA. MARIA RIVER'!AD29 -> 12.888889 | E6: ='STA. MARIA RIVER'!AE29 -> 44.555556 | F6: ='STA. MARIA RIVER'!AF29 -> 7.2141667 | G6: ='STA. MARIA RIVER'!AG29 -> 28.516667 | H6: ='STA. MARIA RIVER'!AH29 -> 24.833333 | I6: ='STA. MARIA RIVER'!AI29 -> 272433.36 | J6: ='STA. MARIA RIVER'!AJ29 -> 0.88311111 | ... L6: ='STA. MARIA RIVER'!AL29 -> 81.638889
A7: Other Water Bodies
A8: Pampanga River | B8: C | C8: ='PAMPANGA RIVER'!U35 -> 4.483 | D8: ='PAMPANGA RIVER'!V35 -> 4.2 | E8: ='PAMPANGA RIVER'!W35 -> 52.15 | F8: ='PAMPANGA RIVER'!X35 -> 7.238 | G8: ='PAMPANGA RIVER'!Y35 -> 28.815 | H8: ='PAMPANGA RIVER'!Z35 -> 20.5 | I8: ='PAMPANGA RIVER'!AA35 -> 7998.5883 | J8: ='PAMPANGA RIVER'!AB35 -> 0.79745 | ... L8: ='PAMPANGA RIVER'!AD35 -> 79.6
A9: Labangan River | B9: C | C9: ='LABANGAN RIVER'!X33 -> 3.9666667 | D9: ='LABANGAN RIVER'!Y33 -> 4.525 | E9: ='LABANGAN RIVER'!Z33 -> 33.5 | F9: ='LABANGAN RIVER'!AA33 -> 7.5441667 | G9: ='LABANGAN RIVER'!AB33 -> 28.641667 | H9: ='LABANGAN RIVER'!AC33 -> 15.416667 | I9: ='LABANGAN RIVER'!AD33 -> 20732.98 | J9: ='LABANGAN RIVER'!AE33 -> 0.21283333 | ... L9: ='LABANGAN RIVER'!AG33 -> 94.333333
A10: Angat River | B10: B | C10: ='ANGAT RIVERS 4L'!AD29 -> 5.9975 | D10: ='ANGAT RIVERS 4L'!AE29 -> 2.5 | E10: ='ANGAT RIVERS 4L'!AF29 -> 15.208333 | F10: ='ANGAT RIVERS 4L'!AG29 -> 7.5091667 | G10: ='ANGAT RIVERS 4L'!AH29 -> 27.958333 | H10: ='ANGAT RIVERS 4L'!AI29 -> 3.7988333 | I10: ='ANGAT RIVERS 4L'!AJ29 -> 14943.04 | J10: ='ANGAT RIVERS 4L'!AK29 -> 0.26066667 | ... L10: ='ANGAT RIVERS 4L'!AM29 -> 21.5
A11: Talavera River | B11: B | C11: ='TALAVERA RIVER'!J64 -> 6.1258333 | D11: ='TALAVERA RIVER'!K64 -> 2.8333333 | E11: ='TALAVERA RIVER'!L64 -> 63.583333 | F11: ='TALAVERA RIVER'!M64 -> 7.4591667 | G11: ='TALAVERA RIVER'!N64 -> 27.758333 | H11: ='TALAVERA RIVER'!O64 -> 5.4166667 | I11: ='TALAVERA RIVER'!P64 -> 5805.9142 | J11: ='TALAVERA RIVER'!Q64 -> 0.49658333 | ... L11: ='TALAVERA RIVER'!S64 -> 11
A12: Bagsit River | B12: B | C12: ='BAGSIT RIVER'!X30 -> 5.9341667 | D12: ='BAGSIT RIVER'!Y30 -> 2.4166667 | E12: ='BAGSIT RIVER'!Z30 -> 17.75 | F12: ='BAGSIT RIVER'!AA30 -> 7.5816667 | G12: ='BAGSIT RIVER'!AB30 -> 27.908333 | H12: ='BAGSIT RIVER'!AC30 -> 5.8333333 | I12: ='BAGSIT RIVER'!AD30 -> 3090.1976 | J12: ='BAGSIT RIVER'!AE30 -> 0.16866667 | ... L12: ='BAGSIT RIVER'!AG30 -> 54.916667
A13: Pudoc River | B13: B | C13: ='PUDOC RIVER (R4L)'!AC16 -> 4.8225 | D13: ='PUDOC RIVER (R4L)'!AD16 -> 2.1875 | E13: ='PUDOC RIVER (R4L)'!AE16 -> 14.25 | F13: ='PUDOC RIVER (R4L)'!AF16 -> 7.194375 | G13: ='PUDOC RIVER (R4L)'!AG16 -> 26.79375 | H13: ='PUDOC RIVER (R4L)'!AH16 -> 14.375 | I13: ='PUDOC RIVER (R4L)'!AI16 -> 30478.526 | J13: ='PUDOC RIVER (R4L)'!AJ16 -> 0.30775 | ... L13: ='PUDOC RIVER (R4L)'!AL16 -> 75.8125
A14: Palakol River | B14: B | C14: ='PALAKOL RIVER (R4L)'!S29 -> 6.0833333 | D14: ='PALAKOL RIVER (R4L)'!T29 -> 2.75 | E14: ='PALAKOL RIVER (R4L)'!U29 -> 31 | F14: ='PALAKOL RIVER (R4L)'!V29 -> 7.455 | G14: ='PALAKOL RIVER (R4L)'!W29 -> 29.091667 | H14: ='PALAKOL RIVER (R4L)'!X29 -> 19.25 | I14: ='PALAKOL RIVER (R4L)'!Y29 -> 14424.817 | J14: ='PALAKOL RIVER (R4L)'!Z29 -> 0.126 | ... L14: ='PALAKOL RIVER (R4L)'!AB29 -> 19.25
A15: Priority Recreational Waterbodies
A16: Bagac Bay | B16: SB | C16: ='MONTEMAR BEACH CLUB'!L59 -> 5.8805556 | D16: ='MONTEMAR BEACH CLUB'!M59 -> N/A | E16: ='MONTEMAR BEACH CLUB'!N59 -> 45.027778 | F16: ='MONTEMAR BEACH CLUB'!O59 -> 7.4355556 | G16: ='MONTEMAR BEACH CLUB'!P59 -> 28.816667 | H16: ='MONTEMAR BEACH CLUB'!Q59 -> 5.1388889 | I16: ='MONTEMAR BEACH CLUB'!R59 -> 69.62787 | J16: ='MONTEMAR BEACH CLUB'!S59 -> 0.12361111 | ... L16: ='MONTEMAR BEACH CLUB'!U59 -> N/A
A17: Baler Bay | B17: SB | C17: ='BALER BAY'!J95 -> 5.7741667 | D17: ='BALER BAY'!K95 -> N/A | E17: ='BALER BAY'!L95 -> 30.375 | F17: ='BALER BAY'!M95 -> 7.3808333 | G17: ='BALER BAY'!N95 -> 27.568056 | H17: ='BALER BAY'!O95 -> 5 | I17: ='BALER BAY'!P95 -> 791.68387 | J17: ='BALER BAY'!Q95 -> 0.15261111 | ... L17: ='BALER BAY'!S95 -> N/A
A18: Morong Bay | B18: SB | C18: ='JUNESS BEACH RESORT'!AG30 -> 5.7983333 | D18: ='JUNESS BEACH RESORT'!AH30 -> N/A | E18: ='JUNESS BEACH RESORT'!AI30 -> 23.194444 | F18: ='JUNESS BEACH RESORT'!AJ30 -> 7.4780556 | G18: ='JUNESS BEACH RESORT'!AK30 -> 29.227778 | H18: ='JUNESS BEACH RESORT'!AL30 -> 5 | I18: ='JUNESS BEACH RESORT'!AM30 -> 223.72151 | J18: ='JUNESS BEACH RESORT'!AN30 -> 0.10983333 | ... L18: ='JUNESS BEACH RESORT'!AP30 -> N/A
A19: Subic Bay | B19: SB | C19: ='SUBIC BAY'!J69 -> 5.92625 | D19: ='SUBIC BAY'!K69 -> N/A | E19: ='SUBIC BAY'!L69 -> 31.6875 | F19: ='SUBIC BAY'!M69 -> 7.4945833 | G19: ='SUBIC BAY'!N69 -> 29.622917 | H19: ='SUBIC BAY'!O69 -> 5 | I19: ='SUBIC BAY'!P69 -> 627.07393 | J19: ='SUBIC BAY'!Q69 -> 3.5837521 | ... L19: ='SUBIC BAY'!S69 -> N/A
A20: Other Recreational Waterbodies
A21: Iba Beach | B21: SB | C21: ='ZAMBALES BAY'!J69 -> 5.8797833 | D21: ='ZAMBALES BAY'!K69 -> N/A | E21: ='ZAMBALES BAY'!L69 -> 33.104167 | F21: ='ZAMBALES BAY'!M69 -> 7.3687689 | G21: ='ZAMBALES BAY'!N69 -> 29.216667 | H21: ='ZAMBALES BAY'!O69 -> 5 | I21: ='ZAMBALES BAY'!P69 -> 207.9159 | J21: ='ZAMBALES BAY'!Q69 -> 0.12235417 | ... L21: ='ZAMBALES BAY'!S69 -> N/A
A23: MMORS
A24: Marilao River | B24: A/C | C24: ='MARILAO RIVER'!AE33 -> 2.7673333 | D24: ='MARILAO RIVER'!AF33 -> 22.383333 | E24: ='MARILAO RIVER'!AG33 -> 28.916667 | F24: ='MARILAO RIVER'!AH33 -> 7.2466667 | G24: ='MARILAO RIVER'!AI33 -> 29.172833 | H24: ='MARILAO RIVER'!AJ33 -> 17.251 | I24: ='MARILAO RIVER'!AK33 -> 4717494 | J24: ='MARILAO RIVER'!AL33 -> 0.47841667 | ... L24: ='MARILAO RIVER'!AN33 -> 242.8
A25: Meycauayan River | B25: C | C25: ='MEYCAUAYAN RIVER'!AA114 -> 2.3230333 | D25: ='MEYCAUAYAN RIVER'!AB114 -> 47.65 | E25: ='MEYCAUAYAN RIVER'!AC114 -> 40.033333 | F25: ='MEYCAUAYAN RIVER'!AD114 -> 7.171 | G25: ='MEYCAUAYAN RIVER'!AE114 -> 27.948333 | H25: ='MEYCAUAYAN RIVER'!AF114 -> 26 | I25: ='MEYCAUAYAN RIVER'!AG114 -> 5209933.5 | J25: ='MEYCAUAYAN RIVER'!AH114 -> 0.45205 | ... L25: ='MEYCAUAYAN RIVER'!AJ114 -> 108.6
A26: Obando River | B26: C | C26: ='OBANDO RIVER'!AC29 -> 3.8513889 | D26: ='OBANDO RIVER'!AD29 -> 17.638889 | E26: ='OBANDO RIVER'!AE29 -> 39.791667 | F26: ='OBANDO RIVER'!AF29 -> 7.2633333 | G26: ='OBANDO RIVER'!AG29 -> 29.124167 | H26: ='OBANDO RIVER'!AH29 -> 16.805556 | I26: ='OBANDO RIVER'!AI29 -> 115196.42 | J26: ='OBANDO RIVER'!AJ29 -> 0.36672222 | ... L26: ='OBANDO RIVER'!AL29 -> 975.80556

Sheet MARILAO RIVER
C1: SUMMARY REPORT OF WATER QUALITY MONITORING DATA
C2: SUBMITTED BY THE REGIONAL OFFICES
C3: CY 2025
C4: MARILAO RIVER
C5: CLASS C ( 5 STATIONS )
A6: Region | B6: Parameter | C6: Stn. No. | D6: Stn. ID | E6: Address | F6: January | G6: February | H6: March | I6: April | J6: May | K6: June | L6: July | M6: August | N6: September | O6: October | P6: November | Q6: December | R6: Average/Geomean | S6: WQG | T6: Code
A7: III | B7: DO (mg/L) | C7: 1 | D7: Marilao-Caloocan Bridge | E7: Loma De Gato, Marilao, Bulacan | F7: 3 | G7: 1.5 | H7: 3.43 | I7: 3.41 | J7: 4.5 | K7: 3.36 | L7: 3.8 | M7: 4.71 | N7: 4.98 | O7: 4.63 | P7: 4.25 | Q7: 4.45 | R7: =IFERROR(AVERAGE(F7:Q7), 0) -> 3.835 | S7: 5 | T7: MAR_1 | Z7: Water Quality Statistical Report
B8: DO (mg/L) | C8: 2 | D8: Prenza Dam | E8: Prenza II, Marilao, Bulacan | F8: 0.1 | G8: 1.68 | H8: 3.7 | I8: 3.28 | J8: 3.6 | K8: 3.15 | L8: 3.2 | M8: 3.89 | N8: 4.9 | O8: 4.53 | P8: 4.11 | Q8: 4.53 | R8: =IFERROR(AVERAGE(F8:Q8), 0) -> 3.3891667 | S8: 5 | T8: MAR_2 | Z8: 1st Semi-Annual 2025
B9: DO (mg/L) | C9: 3 | D9: Expressway Bridge | E9: Patubig, Marilao, Bulacan | F9: 0.1 | G9: 0.45 | H9: 0.95 | I9: 1.81 | J9: 2.1 | K9: 1.63 | L9: 2.15 | M9: 2.46 | N9: 2.93 | O9: 4.6 | P9: 3.58 | Q9: 2.61 | R9: =IFERROR(AVERAGE(F9:Q9), 0) -> 2.1141667 | S9: 5 | T9: MAR_3 | AE9: PARAMETERS
B10: DO (mg/L) | C10: 4 | D10: Mc Arthur Bridge | E10: Tabing Ilog, Marilao, Bulacan | F10: 0.1 | G10: 0.74 | H10: 1.1 | I10: 1.89 | J10: 2 | K10: 1.58 | L10: 2.1 | M10: 3.24 | N10: 3.2 | O10: 5.15 | P10: 3.38 | Q10: 2.61 | R10: =IFERROR(AVERAGE(F10:Q10), 0) -> 2.2575 | S10: 5 | T10: MAR_4 | Z10: Province / Municipality | AA10: Waterbody | AB10: Class | AC10: No. of Station | AD10: Name of Station | AE10: DO | AF10: BOD | AG10: TSS | AH10: pH | AI10: TEMP | AJ10: COLOR | AK10: FECAL COLIFORM | AL10: NITRATES | AM10: PHOSPHATES | AN10: CHLORIDES
B11: DO (mg/L) | C11: 5 | D11: Ibayo Bridge | E11: Ibayo, Marilao, Bulacan | F11: 0.1 | G11: 0.58 | H11: 0.93 | I11: 1.93 | J11: 1.9 | K11: 1.51 | L11: 2.13 | M11: 3.21 | N11: 3.27 | O11: 5.3 | P11: 3.53 | Q11: 2.5 | R11: =IFERROR(AVERAGE(F11:Q11), 0) -> 2.2408333 | S11: 5 | T11: MAR_5 | Z11: MARILAO, BULACAN | AA11: MARILAO RIVER | AB11: C | AC11: 1 | AD11: Ibayo Bridge | AE11: =AVERAGE(F7:K7) -> 3.2 | AF11: =AVERAGE(F12:K12) -> 20.666667 | AG11: =AVERAGE(F17:K17) -> 24.333333 | AH11: =AVERAGE(F22:K22) -> 7.2233333 | AI11: =AVERAGE(F27:K27) -> 28.666667 | AJ11: =AVERAGE(F32:K32) -> 19.166667 | AK11: =GEOMEAN(F37:K37) -> 5994809.8 | AL11: =AVERAGE(F42:K42) -> 0.31033333 | AM11: =AVERAGE(F47:K47) -> 0.9975 | AN11: =AVERAGE(F52:K52) -> 123.33333
B12: BOD (mg/L) | C12: 1 | D12: Marilao-Caloocan Bridge | E12: Loma De Gato, Marilao, Bulacan | F12: 16 | G12: 25 | H12: 24 | I12: 24 | J12: 22 | K12: 13 | L12: 35 | M12: 11 | N12: 12 | O12: 13 | P12: 10 | Q12: 10 | R12: =IFERROR(AVERAGE(F12:Q12), 0) -> 17.916667 | S12: 7 | T12: MAR_1 | AC12: 2 | AD12: Mc Arthur Bridge | AE12: =AVERAGE(F8:K8) -> 2.585 | AF12: =AVERAGE(F13:K13) -> 24.833333 | AG12: =AVERAGE(F18:K18) -> 22.5 | AH12: =AVERAGE(F23:K23) -> 7.12 | AI12: =AVERAGE(F28:K28) -> 28.783333 | AJ12: =AVERAGE(F33:K33) -> 20 | AK12: =GEOMEAN(F38:K38) -> 6315839.6 | AL12: =AVERAGE(F43:K43) -> 0.27 | AM12: =AVERAGE(F48:K48) -> 0.887 | AN12: =AVERAGE(F53:K53) -> 1001.8333
B13: BOD (mg/L) | C13: 2 | D13: Prenza Dam | E13: Prenza II, Marilao, Bulacan | F13: 42 | G13: 18 | H13: 24 | I13: 23 | J13: 29 | K13: 13 | L13: 14 | M13: 12 | N13: 13 | O13: 17 | P13: 11 | Q13: 10 | R13: =IFERROR(AVERAGE(F13:Q13), 0) -> 18.833333 | S13: 7 | T13: MAR_2 | AC13: 3 | AD13: Expressway Bridge | AE13: =AVERAGE(F9:K9) -> 1.1733333 | AF13: =AVERAGE(F14:K14) -> 35 | AG13: =AVERAGE(F19:K19) -> 30 | AH13: =AVERAGE(F24:K24) -> 7.045 | AI13: =AVERAGE(F29:K29) -> 28.848333 | AJ13: =AVERAGE(F34:K34) -> 24.166667 | AK13: =GEOMEAN(F39:K39) -> 7712836.1 | AL13: =AVERAGE(F44:K44) -> 0.52466667 | AM13: =AVERAGE(F49:K49) -> 1.1998333 | AN13: =AVERAGE(F54:K54) -> 342.5
B14: BOD (mg/L) | C14: 3 | D14: Expressway Bridge | E14: Patubig, Marilao, Bulacan | F14: 19 | G14: 36 | H14: 51 | I14: 59 | J14: 29 | K14: 16 | L14: 14 | M14: 19 | N14: 16 | O14: 23 | P14: 12 | Q14: 19 | R14: =IFERROR(AVERAGE(F14:Q14), 0) -> 26.083333 | S14: 7 | T14: MAR_3 | AC14: 4 | AD14: Prenza Dam | AE14: =AVERAGE(F10:K10) -> 1.235 | AF14: =AVERAGE(F15:K15) -> 28.5 | AG14: =AVERAGE(F20:K20) -> 20.166667 | AH14: =AVERAGE(F25:K25) -> 7.0516667 | AI14: =AVERAGE(F30:K30) -> 28.833333 | AJ14: =AVERAGE(F35:K35) -> 23.333333 | AK14: =GEOMEAN(F40:K40) -> 5236948.7 | AL14: =AVERAGE(F45:K45) -> 0.39483333 | AM14: =AVERAGE(F50:K50) -> 0.92116667 | AN14: =AVERAGE(F55:K55) -> 359.5
B15: BOD (mg/L) | C15: 4 | D15: Mc Arthur Bridge | E15: Tabing Ilog, Marilao, Bulacan | F15: 21 | G15: 31 | H15: 50 | I15: 29 | J15: 23 | K15: 17 | L15: 20 | M15: 16 | N15: 11 | O15: 23 | P15: 11 | Q15: 36 | R15: =IFERROR(AVERAGE(F15:Q15), 0) -> 24 | S15: 7 | T15: MAR_4 | AC15: 5 | AD15: Marilao-Caloocan Bridge | AE15: =AVERAGE(F11:K11) -> 1.1583333 | AF15: =AVERAGE(F16:K16) -> 29.666667 | AG15: =AVERAGE(F21:K21) -> 24 | AH15: =AVERAGE(F26:K26) -> 7.045 | AI15: =AVERAGE(F31:K31) -> 28.813333 | AJ15: =AVERAGE(F36:K36) -> 23.333333 | AK15: =GEOMEAN(F41:K41) -> 9425296.6 | AL15: =AVERAGE(F46:K46) -> 0.35133333 | AM15: =AVERAGE(F51:K51) -> 1.0421667 | AN15: =AVERAGE(F56:K56) -> 421.5
B16: BOD (mg/L) | C16: 5 | D16: Ibayo Bridge | E16: Ibayo, Marilao, Bulacan | F16: 29 | G16: 32 | H16: 47 | I16: 32 | J16: 22 | K16: 16 | L16: 19 | M16: 16 | N16: 16 | O16: 25 | P16: 22 | Q16: 25 | R16: =IFERROR(AVERAGE(F16:Q16), 0) -> 25.083333 | S16: 7 | T16: MAR_5
B17: TSS (mg/L) | C17: 1 | D17: Marilao-Caloocan Bridge | E17: Loma De Gato, Marilao, Bulacan | F17: 14 | G17: 15 | H17: 13 | I17: 24 | J17: 55 | K17: 25 | L17: 21 | M17: 29 | N17: 36 | O17: 34 | P17: 31 | Q17: 36 | R17: =IFERROR(AVERAGE(F17:Q17), 0) -> 27.75 | S17: 80 | T17: MAR_1 | Z17: AVERAGE | AE17: =AVERAGE(AE11:AE15) -> 1.8703333 | AF17: =AVERAGE(AF11:AF15) -> 27.733333 | AG17: =AVERAGE(AG11:AG15) -> 24.2 | AH17: =AVERAGE(AH11:AH15) -> 7.097 | AI17: =AVERAGE(AI11:AI15) -> 28.789 | AJ17: =AVERAGE(AJ11:AJ15) -> 22 | AK17: =AVERAGE(AK11:AK15) -> 6937146.2 | AL17: =AVERAGE(AL11:AL15) -> 0.37023333 | ... AN17: =AVERAGE(AN11:AN15) -> 449.73333
B18: TSS (mg/L) | C18: 2 | D18: Prenza Dam | E18: Prenza II, Marilao, Bulacan | F18: 12 | G18: 17 | H18: 17 | I18: 15 | J18: 40 | K18: 34 | L18: 14 | M18: 29 | N18: 86 | O18: 38 | P18: 36 | Q18: 31 | R18: =IFERROR(AVERAGE(F18:Q18), 0) -> 30.75 | S18: 80 | T18: MAR_2 | Z18: MINIMUM | AE18: =MIN(AE11:AE15) -> 1.1583333 | AF18: =MIN(AF11:AF15) -> 20.666667 | AG18: =MIN(AG11:AG15) -> 20.166667 | AH18: =MIN(AH11:AH15) -> 7.045 | AI18: =MIN(AI11:AI15) -> 28.666667 | AJ18: =MIN(AJ11:AJ15) -> 19.166667 | AK18: =MIN(AK11:AK15) -> 5236948.7 | AL18: =MIN(AL11:AL15) -> 0.27 | ... AN18: =MIN(AN11:AN15) -> 123.33333
B19: TSS (mg/L) | C19: 3 | D19: Expressway Bridge | E19: Patubig, Marilao, Bulacan | F19: 15 | G19: 20 | H19: 19 | I19: 16 | J19: 70 | K19: 40 | L19: 23 | M19: 26 | N19: 37 | O19: 39 | P19: 29 | Q19: 40 | R19: =IFERROR(AVERAGE(F19:Q19), 0) -> 31.166667 | S19: 80 | T19: MAR_3 | Z19: MAXIMUM | AE19: =MAX(AE11:AE15) -> 3.2 | AF19: =MAX(AF11:AF15) -> 35 | AG19: =MAX(AG11:AG15) -> 30 | AH19: =MAX(AH11:AH15) -> 7.2233333 | AI19: =MAX(AI11:AI15) -> 28.848333 | AJ19: =MAX(AJ11:AJ15) -> 24.166667 | AK19: =MAX(AK11:AK15) -> 9425296.6 | AL19: =MAX(AL11:AL15) -> 0.52466667 | ... AN19: =MAX(AN11:AN15) -> 1001.8333
B20: TSS (mg/L) | C20: 4 | D20: Mc Arthur Bridge | E20: Tabing Ilog, Marilao, Bulacan | F20: 16 | G20: 13 | H20: 19 | I20: 11 | J20: 28 | K20: 34 | L20: 28 | M20: 33 | N20: 33 | O20: 32 | P20: 34 | Q20: 45 | R20: =IFERROR(AVERAGE(F20:Q20), 0) -> 27.166667 | S20: 80 | T20: MAR_4 | Z20: STANDARD | AE20: 5 mg/L | AF20: 7 mg/L | AG20: 80 mg/L | AH20: 6.5-9.0 | AI20: 25-31 °C | AJ20: 75 TCU | AK20: 200 MPN/100 L | AL20: 7 mg/L | AM20: 0.025 mg/L | AN20: 350 mg/L
B21: TSS (mg/L) | C21: 5 | D21: Ibayo Bridge | E21: Ibayo, Marilao, Bulacan | F21: 24 | G21: 13 | H21: 30 | I21: 19 | J21: 19 | K21: 39 | L21: 16 | M21: 32 | N21: 32 | O21: 29 | P21: 28 | Q21: 52 | R21: =IFERROR(AVERAGE(F21:Q21), 0) -> 27.75 | S21: 80 | T21: MAR_5
B22: pH | C22: 1 | D22: Marilao-Caloocan Bridge | E22: Loma De Gato, Marilao, Bulacan | F22: 7.1 | G22: 7.14 | H22: 7.08 | I22: 7.13 | J22: 7.8 | K22: 7.09 | L22: 7.2 | M22: 7.28 | N22: 7.38 | O22: 7.77 | P22: 7.48 | Q22: 7.63 | R22: =IFERROR(AVERAGE(F22:Q22), 0) -> 7.34 | S22: 6.5-9.0 | T22: MAR_1
B23: pH | C23: 2 | D23: Prenza Dam | E23: Prenza II, Marilao, Bulacan | F23: 7.1 | G23: 7 | H23: 7.11 | I23: 7.11 | J23: 7.3 | K23: 7.1 | L23: 7.15 | M23: 7.25 | N23: 7.41 | O23: 7.69 | P23: 7.48 | Q23: 7.58 | R23: =IFERROR(AVERAGE(F23:Q23), 0) -> 7.2733333 | S23: 6.5-9.0 | T23: MAR_2 | Z23: Water Quality Statistical Report
B24: pH | C24: 3 | D24: Expressway Bridge | E24: Patubig, Marilao, Bulacan | F24: 7 | G24: 7 | H24: 7.05 | I24: 7.01 | J24: 7.19 | K24: 7.02 | L24: 7.19 | M24: 7.21 | N24: 7.29 | O24: 7.57 | P24: 7.53 | Q24: 7.38 | R24: =IFERROR(AVERAGE(F24:Q24), 0) -> 7.2033333 | S24: 6.5-9.0 | T24: MAR_3 | Z24: Annual 2025
B25: pH | C25: 4 | D25: Mc Arthur Bridge | E25: Tabing Ilog, Marilao, Bulacan | F25: 7 | G25: 7.01 | H25: 7.1 | I25: 7.01 | J25: 7.18 | K25: 7.01 | L25: 7.2 | M25: 7.18 | N25: 7.19 | O25: 7.7 | P25: 7.39 | Q25: 7.39 | R25: =IFERROR(AVERAGE(F25:Q25), 0) -> 7.1966667 | S25: 6.5-9.0 | T25: MAR_4 | AE25: PARAMETERS
B26: pH | C26: 5 | D26: Ibayo Bridge | E26: Ibayo, Marilao, Bulacan | F26: 7 | G26: 7.15 | H26: 7.01 | I26: 6.98 | J26: 7.15 | K26: 6.98 | L26: 7.15 | M26: 7.25 | N26: 7.23 | O26: 7.8 | P26: 7.41 | Q26: 7.53 | R26: =IFERROR(AVERAGE(F26:Q26), 0) -> 7.22 | S26: 6.5-9.0 | T26: MAR_5 | Z26: Province / Municipality | AA26: Waterbody | AB26: Class | AC26: No. of Station | AD26: Name of Station | AE26: DO | AF26: BOD | AG26: TSS | AH26: pH | AI26: TEMP | AJ26: COLOR | AK26: FECAL COLIFORM | AL26: NITRATES | AM26: PHOSPHATES | AN26: CHLORIDES
B27: Temp. (°C) | C27: 1 | D27: Marilao-Caloocan Bridge | E27: Loma De Gato, Marilao, Bulacan | F27: 27.1 | G27: 28.6 | H27: 29.3 | I27: 31.7 | J27: 26.5 | K27: 28.8 | L27: 33.7 | M27: 29.2 | N27: 29 | O27: 27.8 | P27: 29 | Q27: 29.8 | R27: =IFERROR(AVERAGE(F27:Q27), 0) -> 29.208333 | S27: 25-31 | T27: MAR_1 | Z27: MARILAO, BULACAN | AA27: MARILAO RIVER | AB27: C | AC27: 1 | AD27: Ibayo Bridge | AE27: =R7 -> 3.835 | AF27: =R12 -> 17.916667 | AG27: =R17 -> 27.75 | AH27: =R22 -> 7.34 | AI27: =R27 -> 29.208333 | AJ27: =R32 -> 14.634083 | AK27: =R37 -> 3323921.5 | AL27: =R42 -> 0.578 | AM27: =R47 -> 0.82425 | AN27: =R52 -> 73.583333
B28: Temp. (°C) | C28: 2 | D28: Prenza Dam | E28: Prenza II, Marilao, Bulacan | F28: 27 | G28: 29 | H28: 29.4 | I28: 31.7 | J28: 26.8 | K28: 28.8 | L28: 33.9 | M28: 29 | N28: 28.8 | O28: 27.8 | P28: 28.9 | Q28: 29.5 | R28: =IFERROR(AVERAGE(F28:Q28), 0) -> 29.216667 | S28: 25-31 | T28: MAR_2 | AC28: 2 | AD28: Mc Arthur Bridge | AE28: =R8 -> 3.3891667 | AF28: =R13 -> 18.833333 | AG28: =R18 -> 30.75 | AH28: =R23 -> 7.2733333 | AI28: =R28 -> 29.216667 | AJ28: =R33 -> 15.465917 | AK28: =R38 -> 4518250.9 | AL28: =R43 -> 0.53791667 | AM28: =R48 -> 0.76116667 | AN28: =R53 -> 514.33333
B29: Temp. (°C) | C29: 3 | D29: Expressway Bridge | E29: Patubig, Marilao, Bulacan | F29: 26.8 | G29: 29.29 | H29: 29 | I29: 31.1 | J29: 27.1 | K29: 29.8 | L29: 33.8 | M29: 28.7 | N29: 29.1 | O29: 27.9 | P29: 29 | Q29: 29.1 | R29: =IFERROR(AVERAGE(F29:Q29), 0) -> 29.224167 | S29: 25-31 | T29: MAR_3 | AC29: 3 | AD29: Expressway Bridge | AE29: =R9 -> 2.1141667 | AF29: =R14 -> 26.083333 | AG29: =R19 -> 31.166667 | AH29: =R24 -> 7.2033333 | AI29: =R29 -> 29.224167 | AJ29: =R34 -> 19.32075 | AK29: =R39 -> 6046951.5 | AL29: =R44 -> 0.4815 | AM29: =R49 -> 1.0780833 | AN29: =R54 -> 193.58333
B30: Temp. (°C) | C30: 4 | D30: Mc Arthur Bridge | E30: Tabing Ilog, Marilao, Bulacan | F30: 26.8 | G30: 29.2 | H30: 28.9 | I30: 31 | J30: 27.3 | K30: 29.8 | L30: 33.7 | M30: 28.5 | N30: 29.1 | O30: 27.6 | P30: 29 | Q30: 29.1 | R30: =IFERROR(AVERAGE(F30:Q30), 0) -> 29.166667 | S30: 25-31 | T30: MAR_4 | AC30: 4 | AD30: Prenza Dam | AE30: =R10 -> 2.2575 | AF30: =R15 -> 24 | AG30: =R20 -> 27.166667 | AH30: =R25 -> 7.1966667 | AI30: =R30 -> 29.166667 | AJ30: =R35 -> 18.4025 | AK30: =R40 -> 3068204 | AL30: =R45 -> 0.42033333 | AM30: =R50 -> 0.85616667 | AN30: =R55 -> 198.66667
B31: Temp. (°C) | C31: 5 | D31: Ibayo Bridge | E31: Ibayo, Marilao, Bulacan | F31: 26.7 | G31: 29.98 | H31: 29.1 | I31: 30.1 | J31: 27.5 | K31: 29.5 | L31: 33.9 | M31: 27.8 | N31: 28 | O31: 27.6 | P31: 28.9 | Q31: 29.5 | R31: =IFERROR(AVERAGE(F31:Q31), 0) -> 29.048333 | S31: 25-31 | T31: MAR_5 | AC31: 5 | AD31: Marilao-Caloocan Bridge | AE31: =R11 -> 2.2408333 | AF31: =R16 -> 25.083333 | AG31: =R21 -> 27.75 | AH31: =R26 -> 7.22 | AI31: =R31 -> 29.048333 | AJ31: =R36 -> 18.43175 | AK31: =R41 -> 6630142.4 | AL31: =R46 -> 0.37433333 | AM31: =R51 -> 0.91425 | AN31: =R56 -> 233.83333
B32: Color (TCU) | C32: 1 | D32: Marilao-Caloocan Bridge | E32: Loma De Gato, Marilao, Bulacan | F32: 15 | G32: 10 | H32: 20 | I32: 25 | J32: 25 | K32: 20 | L32: 15 | M32: 15 | N32: 0.609 | O32: 10 | P32: 10 | Q32: 10 | R32: =IFERROR(AVERAGE(F32:Q32), 0) -> 14.634083 | S32: 75 | T32: MAR_1
B33: Color (TCU) | C33: 2 | D33: Prenza Dam | E33: Prenza II, Marilao, Bulacan | F33: 15 | G33: 15 | H33: 20 | I33: 25 | J33: 25 | K33: 20 | L33: 15 | M33: 15 | N33: 0.591 | O33: 10 | P33: 10 | Q33: 15 | R33: =IFERROR(AVERAGE(F33:Q33), 0) -> 15.465917 | S33: 75 | T33: MAR_2 | Z33: AVERAGE | AE33: =AVERAGE(AE27:AE31) -> 2.7673333 | AF33: =AVERAGE(AF27:AF31) -> 22.383333 | AG33: =AVERAGE(AG27:AG31) -> 28.916667 | AH33: =AVERAGE(AH27:AH31) -> 7.2466667 | AI33: =AVERAGE(AI27:AI31) -> 29.172833 | AJ33: =AVERAGE(AJ27:AJ31) -> 17.251 | AK33: =AVERAGE(AK27:AK31) -> 4717494 | AL33: =AVERAGE(AL27:AL31) -> 0.47841667 | ... AN33: =AVERAGE(AN27:AN31) -> 242.8
B34: Color (TCU) | C34: 3 | D34: Expressway Bridge | E34: Patubig, Marilao, Bulacan | F34: 20 | G34: 25 | H34: 25 | I34: 30 | J34: 25 | K34: 20 | L34: 20 | M34: 20 | N34: 1.849 | O34: 15 | P34: 15 | Q34: 15 | R34: =IFERROR(AVERAGE(F34:Q34), 0) -> 19.32075 | S34: 75 | T34: MAR_3 | Z34: MINIMUM | AE34: =MIN(AE27:AE31) -> 2.1141667 | AF34: =MIN(AF27:AF31) -> 17.916667 | AG34: =MIN(AG27:AG31) -> 27.166667 | AH34: =MIN(AH27:AH31) -> 7.1966667 | AI34: =MIN(AI27:AI31) -> 29.048333 | AJ34: =MIN(AJ27:AJ31) -> 14.634083 | AK34: =MIN(AK27:AK31) -> 3068204 | AL34: =MIN(AL27:AL31) -> 0.37433333 | ... AN34: =MIN(AN27:AN31) -> 73.583333
B35: Color (TCU) | C35: 4 | D35: Mc Arthur Bridge | E35: Tabing Ilog, Marilao, Bulacan | F35: 20 | G35: 25 | H35: 30 | I35: 30 | J35: 25 | K35: 10 | L35: 15 | M35: 20 | N35: 0.83 | O35: 10 | P35: 15 | Q35: 20 | R35: =IFERROR(AVERAGE(F35:Q35), 0) -> 18.4025 | S35: 75 | T35: MAR_4 | Z35: MAXIMUM | AE35: =MAX(AE27:AE31) -> 3.835 | AF35: =MAX(AF27:AF31) -> 26.083333 | AG35: =MAX(AG27:AG31) -> 31.166667 | AH35: =MAX(AH27:AH31) -> 7.34 | AI35: =MAX(AI27:AI31) -> 29.224167 | AJ35: =MAX(AJ27:AJ31) -> 19.32075 | AK35: =MAX(AK27:AK31) -> 6630142.4 | AL35: =MAX(AL27:AL31) -> 0.578 | ... AN35: =MAX(AN27:AN31) -> 514.33333
B36: Color (TCU) | C36: 5 | D36: Ibayo Bridge | E36: Ibayo, Marilao, Bulacan | F36: 20 | G36: 25 | H36: 30 | I36: 30 | J36: 25 | K36: 10 | L36: 20 | M36: 15 | N36: 1.181 | O36: 15 | P36: 15 | Q36: 15 | R36: =IFERROR(AVERAGE(F36:Q36), 0) -> 18.43175 | S36: 75 | T36: MAR_5 | Z36: STANDARD | AE36: 5 mg/L | AF36: 7 mg/L | AG36: 80 mg/L | AH36: 6.5-9.0 | AI36: 25-31 °C | AJ36: 75 TCU | AK36: 200 MPN/100 L | AL36: 7 mg/L | AM36: 0.025 mg/L | AN36: 350 mg/L
B37: Fecal Coliform (MPN/100mL) | C37: 1 | D37: Marilao-Caloocan Bridge | E37: Loma De Gato, Marilao, Bulacan | F37: 1300000 | G37: 9200000 | H37: 6300000 | I37: 11000000 | J37: 16000000 | K37: 3500000 | L37: 2400000 | M37: 54000000 | N37: 49000 | O37: 11000000 | P37: 1700000 | Q37: 330000 | R37: =IFERROR(GEOMEAN(F37:Q37), 0) -> 3323921.5 | S37: 200 | T37: MAR_1
B38: Fecal Coliform (MPN/100mL) | C38: 2 | D38: Prenza Dam | E38: Prenza II, Marilao, Bulacan | F38: 16000000 | G38: 3500000 | H38: 9200000 | I38: 7000000 | J38: 16000000 | K38: 1100000 | L38: 1700000 | M38: 35000000 | N38: 2400000 | O38: 11000000 | P38: 2200000 | Q38: 330000 | R38: =IFERROR(GEOMEAN(F38:Q38), 0) -> 4518250.9 | S38: 200 | T38: MAR_2
B39: Fecal Coliform (MPN/100mL) | C39: 3 | D39: Expressway Bridge | E39: Patubig, Marilao, Bulacan | F39: 17000000 | G39: 6500000 | H39: 35000000 | I39: 5400000 | J39: 16000000 | K39: 630000 | L39: 2400000 | M39: 24000000 | N39: 700000 | O39: 16000000 | P39: 1100000 | Q39: 16000000 | R39: =IFERROR(GEOMEAN(F39:Q39), 0) -> 6046951.5 | S39: 200 | T39: MAR_3
B40: Fecal Coliform (MPN/100mL) | C40: 4 | D40: Mc Arthur Bridge | E40: Tabing Ilog, Marilao, Bulacan | F40: 11000000 | G40: 7000000 | H40: 9200000 | I40: 1400000 | J40: 16000000 | K40: 1300000 | L40: 3500000 | M40: 92000000 | N40: 33000 | O40: 1200000 | P40: 490000 | Q40: 5400000 | R40: =IFERROR(GEOMEAN(F40:Q40), 0) -> 3068204 | S40: 200 | T40: MAR_4
...

Sheet MEYCAUAYAN RIVER
C1: SUMMARY REPORT OF WATER QUALITY MONITORING DATA
C2: SUBMITTED BY THE REGIONAL OFFICES
C3: CY 2025
C4: MEYCAUAYAN RIVER
C5: CLASS C ( 5 STATIONS )
A6: Region | B6: Parameter | C6: Stn. No. | D6: Stn. ID | E6: Address | F6: January | G6: February | H6: March | I6: April | J6: May | K6: June | L6: July | M6: August | N6: September | O6: October | P6: November | Q6: December | R6: Average/Geomean | S6: WQG | T6: Code
A7: III | B7: DO (mg/L) | C7: 1 | D7: Perez Bridge | E7: Pantoc, Meycauayan, Bulacan | F7: 0.1 | G7: 1.03 | H7: 1.05 | I7: 2.39 | J7: 3.21 | K7: 3.99 | L7: 4.25 | M7: 4.1 | N7: 4.01 | O7: 3.05 | P7: 3.9 | Q7: 3.202 | R7: =IFERROR(AVERAGE(F7:Q7), 0) -> 2.8568333 | S7: 5 | T7: MEY_1
B8: DO (mg/L) | C8: 2 | D8: Expressway Bridge | E8: Lawa, Meycauayan, Bulacan | F8: 0.1 | G8: 0.9 | H8: 1.01 | I8: 1.32 | J8: 1.15 | K8: 3.12 | L8: 4.09 | M8: 3.01 | N8: 0.8 | O8: 3.08 | P8: 2.7 | Q8: 2.99 | R8: =IFERROR(AVERAGE(F8:Q8), 0) -> 2.0225 | S8: 5 | T8: MEY_2
B9: DO (mg/L) | C9: 3 | D9: Viente Reales Bridge | E9: Viente Reales, Valenzuela, Metro Manila | F9: 0.1 | G9: 1.02 | H9: 2.3 | I9: 1.71 | J9: 3.05 | K9: 3.11 | L9: 4.15 | M9: 3.9 | N9: 0.5 | O9: 3.81 | P9: 4.95 | Q9: 4.53 | R9: =IFERROR(AVERAGE(F9:Q9), 0) -> 2.7608333 | S9: 5 | T9: MEY_3
B10: DO (mg/L) | C10: 4 | D10: McArthur Highway | E10: Calvario, Meycauayan, Bulacan | F10: 0.1 | G10: 1 | H10: 0.68 | I10: 1.09 | J10: 1.69 | K10: 2.28 | L10: 3.61 | M10: 2.93 | N10: 0.9 | O10: 2.85 | P10: 2.6 | Q10: 2.11 | R10: =IFERROR(AVERAGE(F10:Q10), 0) -> 1.82 | S10: 5 | T10: MEY_4
B11: DO (mg/L) | C11: 5 | D11: Meymart Bridge | E11: Poblacion, Meycauayan, Bulacan | F11: 0.1 | G11: 0.89 | H11: 0.67 | I11: 1.11 | J11: 1.71 | K11: 2.18 | L11: 3.59 | M11: 2.91 | N11: 1.01 | O11: 4.05 | P11: 2.99 | Q11: 4.65 | R11: =IFERROR(AVERAGE(F11:Q11), 0) -> 2.155 | S11: 5 | T11: MEY_5
B12: BOD (mg/L) | C12: 1 | D12: Perez Bridge | E12: Pantoc, Meycauayan, Bulacan | F12: 33 | G12: 35 | H12: 44 | I12: 28 | J12: 34 | K12: 15 | L12: 11 | M12: 13 | N12: 29 | O12: 27 | P12: 28 | Q12: 31 | R12: =IFERROR(AVERAGE(F12:Q12), 0) -> 27.333333 | S12: 7 | T12: MEY_1
B13: BOD (mg/L) | C13: 2 | D13: Expressway Bridge | E13: Lawa, Meycauayan, Bulacan | F13: 96 | G13: 96 | H13: 108 | I13: 86 | J13: 112 | K13: 61 | L13: 9 | M13: 20 | N13: 33 | O13: 56 | P13: 25 | Q13: 118 | R13: =IFERROR(AVERAGE(F13:Q13), 0) -> 68.333333 | S13: 7 | T13: MEY_2
B14: BOD (mg/L) | C14: 3 | D14: Viente Reales Bridge | E14: Viente Reales, Valenzuela, Metro Manila | F14: 85 | G14: 86 | H14: 41 | I14: 184 | J14: 14 | K14: 47 | L14: 17 | M14: 17 | N14: 31 | O14: 7 | P14: 18 | Q14: 73 | R14: =IFERROR(AVERAGE(F14:Q14), 0) -> 51.666667 | S14: 7 | T14: MEY_3
B15: BOD (mg/L) | C15: 4 | D15: McArthur Highway | E15: Calvario, Meycauayan, Bulacan | F15: 75 | G15: 58 | H15: 72 | I15: 59 | J15: 19 | K15: 18 | L15: 9 | M15: 10 | N15: 19 | O15: 44 | P15: 102 | Q15: 119 | R15: =IFERROR(AVERAGE(F15:Q15), 0) -> 50.333333 | S15: 7 | T15: MEY_4
B16: BOD (mg/L) | C16: 5 | D16: Meymart Bridge | E16: Poblacion, Meycauayan, Bulacan | F16: 45 | G16: 48 | H16: 54 | I16: 39 | J16: 23 | K16: 31 | L16: 13 | M16: 27 | N16: 28 | O16: 63 | P16: 19 | Q16: 97 | R16: =IFERROR(AVERAGE(F16:Q16), 0) -> 40.583333 | S16: 7 | T16: MEY_5
B17: TSS (mg/L) | C17: 1 | D17: Perez Bridge | E17: Pantoc, Meycauayan, Bulacan | F17: 13 | G17: 12 | H17: 24 | I17: 13 | J17: 70 | K17: 37 | L17: 18 | M17: 29 | N17: 29 | O17: 26 | P17: 39 | Q17: 54 | R17: =IFERROR(AVERAGE(F17:Q17), 0) -> 30.333333 | S17: 80 | T17: MEY_1
B18: TSS (mg/L) | C18: 2 | D18: Expressway Bridge | E18: Lawa, Meycauayan, Bulacan | F18: 35 | G18: 100 | H18: 42 | I18: 18 | J18: 60 | K18: 51 | L18: 16 | M18: 31 | N18: 31 | O18: 25 | P18: 37 | Q18: 59 | R18: =IFERROR(AVERAGE(F18:Q18), 0) -> 42.083333 | S18: 80 | T18: MEY_2
B19: TSS (mg/L) | C19: 3 | D19: Viente Reales Bridge | E19: Viente Reales, Valenzuela, Metro Manila | F19: 21 | G19: 30 | H19: 25 | I19: 62 | J19: 37 | K19: 57 | L19: 29 | M19: 36 | N19: 44 | O19: 32 | P19: 44 | Q19: 46 | R19: =IFERROR(AVERAGE(F19:Q19), 0) -> 38.583333 | S19: 80 | T19: MEY_3
... B21: TSS (mg/L) | C21: 5 | D21: Meymart Bridge | E21: Poblacion, Meycauayan, Bulacan | F21: 30 | G21: 17 | H21: 36 | I21: 30 | J21: 63 | K21: 48 | L21: 32 | M21: 27 | N21: 43 | O21: 26 | P21: 41 | Q21: 36 | R21: =IFERROR(AVERAGE(F21:Q21), 0) -> 35.75 | S21: 80 | T21: MEY_5
B22: pH | C22: 1 | D22: Perez Bridge | E22: Pantoc, Meycauayan, Bulacan | F22: 7.1 | G22: 7.05 | H22: 7.1 | I22: 6.96 | J22: 7.01 | K22: 7.1 | L22: 7.11 | M22: 7.55 | N22: 7.93 | O22: 7.15 | P22: 7.31 | Q22: 7.09 | R22: =IFERROR(AVERAGE(F22:Q22), 0) -> 7.205 | S22: 6.5-9.0 | T22: MEY_1
B23: pH | C23: 2 | D23: Expressway Bridge | E23: Lawa, Meycauayan, Bulacan | F23: 6.98 | G23: 6.97 | H23: 6.99 | I23: 7.1 | J23: 6.89 | K23: 7.03 | L23: 7.11 | M23: 7.65 | N23: 7.85 | O23: 7.2 | P23: 7.1 | Q23: 7.13 | R23: =IFERROR(AVERAGE(F23:Q23), 0) -> 7.1666667 | S23: 6.5-9.0 | T23: MEY_2
B24: pH | C24: 3 | D24: Viente Reales Bridge | E24: Viente Reales, Valenzuela, Metro Manila | F24: 7 | G24: 7.03 | H24: 7.01 | I24: 6.85 | J24: 7.05 | K24: 7.1 | L24: 7.13 | M24: 7.58 | N24: 7.91 | O24: 7.27 | P24: 7.21 | Q24: 7.1 | R24: =IFERROR(AVERAGE(F24:Q24), 0) -> 7.1866667 | S24: 6.5-9.0 | T24: MEY_3
B25: pH | C25: 4 | D25: McArthur Highway | E25: Calvario, Meycauayan, Bulacan | F25: 6.9 | G25: 7 | H25: 6.99 | I25: 7.1 | J25: 6.98 | K25: 6.98 | L25: 7.11 | M25: 7.5 | N25: 7.92 | O25: 7.08 | P25: 7.18 | Q25: 7.01 | R25: =IFERROR(AVERAGE(F25:Q25), 0) -> 7.1458333 | S25: 6.5-9.0 | T25: MEY_4
B26: pH | C26: 5 | D26: Meymart Bridge | E26: Poblacion, Meycauayan, Bulacan | F26: 6.95 | G26: 6.98 | H26: 6.98 | I26: 6.96 | J26: 6.93 | K26: 6.93 | L26: 7.03 | M26: 7.59 | N26: 7.67 | O26: 7.38 | P26: 7.13 | Q26: 7.28 | R26: =IFERROR(AVERAGE(F26:Q26), 0) -> 7.1508333 | S26: 6.5-9.0 | T26: MEY_5
B27: Temp. (°C) | C27: 1 | D27: Perez Bridge | E27: Pantoc, Meycauayan, Bulacan | F27: 27.1 | G27: 26.1 | H27: 28.1 | I27: 30 | J27: 29.1 | K27: 28 | L27: 26.5 | M27: 28.8 | N27: 28.4 | O27: 26.2 | P27: 30 | Q27: 27.1 | R27: =IFERROR(AVERAGE(F27:Q27), 0) -> 27.95 | S27: 25-31 | T27: MEY_1
B28: Temp. (°C) | C28: 2 | D28: Expressway Bridge | E28: Lawa, Meycauayan, Bulacan | F28: 27 | G28: 25.9 | H28: 27.5 | I28: 29.9 | J28: 29 | K28: 27.8 | L28: 26.5 | M28: 28.8 | N28: 28.4 | O28: 26.2 | P28: 29.9 | Q28: 27.1 | R28: =IFERROR(AVERAGE(F28:Q28), 0) -> 27.833333 | S28: 25-31 | T28: MEY_2
B29: Temp. (°C) | C29: 3 | D29: Viente Reales Bridge | E29: Viente Reales, Valenzuela, Metro Manila | F29: 27.1 | G29: 26.1 | H29: 27.5 | I29: 29.9 | J29: 29.8 | K29: 27.8 | L29: 26.5 | M29: 28.8 | N29: 28 | O29: 26.8 | P29: 29.8 | Q29: 27 | R29: =IFERROR(AVERAGE(F29:Q29), 0) -> 27.925 | S29: 25-31 | T29: MEY_3
B30: Temp. (°C) | C30: 4 | D30: McArthur Highway | E30: Calvario, Meycauayan, Bulacan | F30: 27.1 | G30: 26 | H30: 27.3 | I30: 30.8 | J30: 29.1 | K30: 27.4 | L30: 26.8 | M30: 30.1 | N30: 27.9 | O30: 26.7 | P30: 29.8 | Q30: 27.1 | R30: =IFERROR(AVERAGE(F30:Q30), 0) -> 28.008333 | S30: 25-31 | T30: MEY_4
B31: Temp. (°C) | C31: 5 | D31: Meymart Bridge | E31: Poblacion, Meycauayan, Bulacan | F31: 27 | G31: 25.9 | H31: 27.1 | I31: 30.9 | J31: 29.1 | K31: 27.4 | L31: 26.8 | M31: 31 | N31: 27.5 | O31: 26.7 | P31: 29.8 | Q31: 27.1 | R31: =IFERROR(AVERAGE(F31:Q31), 0) -> 28.025 | S31: 25-31 | T31: MEY_5
B32: Color (TCU) | C32: 1 | D32: Perez Bridge | E32: Pantoc, Meycauayan, Bulacan | F32: 50 | G32: 30 | H32: 40 | I32: 30 | J32: 35 | K32: 20 | L32: 10 | M32: 20 | N32: 20 | O32: 25 | P32: 20 | Q32: 20 | R32: =IFERROR(AVERAGE(F32:Q32), 0) -> 26.666667 | S32: 75 | T32: MEY_1
B33: Color (TCU) | C33: 2 | D33: Expressway Bridge | E33: Lawa, Meycauayan, Bulacan | F33: 50 | G33: 25 | H33: 30 | I33: 30 | J33: 50 | K33: 35 | L33: 20 | M33: 20 | N33: 15 | O33: 35 | P33: 30 | Q33: 40 | R33: =IFERROR(AVERAGE(F33:Q33), 0) -> 31.666667 | S33: 75 | T33: MEY_2
B34: Color (TCU) | C34: 3 | D34: Viente Reales Bridge | E34: Viente Reales, Valenzuela, Metro Manila | F34: 25 | G34: 25 | H34: 10 | I34: 30 | J34: 10 | K34: 20 | L34: 10 | M34: 10 | N34: 15 | O34: 5 | P34: 5 | Q34: 10 | R34: =IFERROR(AVERAGE(F34:Q34), 0) -> 14.583333 | S34: 75 | T34: MEY_3
B35: Color (TCU) | C35: 4 | D35: McArthur Highway | E35: Calvario, Meycauayan, Bulacan | F35: 50 | G35: 50 | H35: 30 | I35: 25 | J35: 20 | K35: 15 | L35: 15 | M35: 20 | N35: 15 | O35: 30 | P35: 40 | Q35: 30 | R35: =IFERROR(AVERAGE(F35:Q35), 0) -> 28.333333 | S35: 75 | T35: MEY_4
B36: Color (TCU) | C36: 5 | D36: Meymart Bridge | E36: Poblacion, Meycauayan, Bulacan | F36: 50 | G36: 50 | H36: 30 | I36: 25 | J36: 20 | K36: 15 | L36: 15 | M36: 20 | N36: 20 | O36: 20 | P36: 40 | Q36: 40 | R36: =IFERROR(AVERAGE(F36:Q36), 0) -> 28.75 | S36: 75 | T36: MEY_5
B37: Fecal Coliform (MPN/100mL) | C37: 1 | D37: Perez Bridge | E37: Pantoc, Meycauayan, Bulacan | F37: 7900000 | G37: 9200000 | H37: 16000000 | I37: 17000000 | J37: 920000000 | K37: 460000 | L37: 1100000 | M37: 9200000 | N37: 1300000 | O37: 35000000 | P37: 11000000 | Q37: 3500000 | R37: =IFERROR(GEOMEAN(F37:Q37), 0) -> 8529662.4 | S37: 200 | T37: MEY_1
B38: Fecal Coliform (MPN/100mL) | C38: 2 | D38: Expressway Bridge | E38: Lawa, Meycauayan, Bulacan | F38: 13000000 | G38: 54000000 | H38: 5400000 | I38: 11000000 | J38: 490000 | K38: 1700000 | L38: 3500000 | M38: 5400000 | N38: 16000000 | O38: 16000000 | P38: 1700000 | Q38: 16000000 | R38: =IFERROR(GEOMEAN(F38:Q38), 0) -> 6382682.9 | S38: 200 | T38: MEY_2
B39: Fecal Coliform (MPN/100mL) | C39: 3 | D39: Viente Reales Bridge | E39: Viente Reales, Valenzuela, Metro Manila | F39: 3300000 | G39: 54000000 | H39: 35000000 | I39: 35000000 | J39: 5400000 | K39: 9200000 | L39: 3500000 | M39: 1300000 | N39: 230000 | O39: 1700000 | P39: 3500000 | Q39: 16000000 | R39: =IFERROR(GEOMEAN(F39:Q39), 0) -> 5659787.6 | S39: 200 | T39: MEY_3
B40: Fecal Coliform (MPN/100mL) | C40: 4 | D40: McArthur Highway | E40: Calvario, Meycauayan, Bulacan | F40: 11000000 | G40: 9200000 | H40: 5400000 | I40: 3500000 | J40: 940000 | K40: 490000 | L40: 790000 | M40: 3500000 | N40: 1700000 | O40: 2500000 | P40: 9200000 | Q40: 2400000 | R40: =IFERROR(GEOMEAN(F40:Q40), 0) -> 2796323.7 | S40: 200 | T40: MEY_4
B41: Fecal Coliform (MPN/100mL) | C41: 5 | D41: Meymart Bridge | E41: Poblacion, Meycauayan, Bulacan | F41: 4600000 | G41: 35000000 | H41: 3500000 | I41: 490000 | J41: 230000 | K41: 3300000 | L41: 1100000 | M41: 1200000 | N41: 11000000 | O41: 5400000 | P41: 3500000 | Q41: 2400000 | R41: =IFERROR(GEOMEAN(F41:Q41), 0) -> 2681210.8 | S41: 200 | T41: MEY_5 | U41: =GEOMEAN(F37:Q41) -> 4706854
...

Sheet OBANDO RIVER
C1: SUMMARY REPORT OF WATER QUALITY MONITORING DATA
C2: SUBMITTED BY THE REGIONAL OFFICES
C3: CY 2025
C4: OBANDO RIVER
C5: CLASS C ( 3 STATIONS )
A6: Region | B6: Parameter | C6: Stn. No. | D6: Stn. ID | E6: Address | F6: January | G6: February | H6: March | I6: April | J6: May | K6: June | L6: July | M6: August | N6: September | O6: October | P6: November | Q6: December | R6: Average/Geomean | S6: WQG | T6: Code
A7: III | B7: DO (mg/L) | C7: 1 | D7: Polo Bridge | E7: Polo, Valenzuela City, Metro Manila | F7: 6.5 | G7: 4.24 | H7: 6 | I7: 5.18 | J7: 5.65 | K7: 5.1 | L7: 5.6 | M7: 4.32 | N7: 5.13 | O7: 4.53 | P7: 2.85 | Q7: 5.01 | R7: =IFERROR(AVERAGE(F7:Q7), 0) -> 5.0091667 | S7: 5 | T7: OBN_1 | X7: Water Quality Statistical Report
B8: DO (mg/L) | C8: 2 | D8: Fishport Near Public Market | E8: Paliwas, Obando, Bulacan | F8: 0.2 | G8: 1.35 | H8: 0.9 | I8: 1.07 | J8: 4.65 | K8: 6 | L8: 2.6 | M8: 3.25 | N8: 3.18 | O8: 3.58 | P8: 3.83 | Q8: 2.61 | R8: =IFERROR(AVERAGE(F8:Q8), 0) -> 2.7683333 | S8: 5 | T8: OBN_2 | X8: 1st Semi-Annual 2025
B9: DO (mg/L) | C9: 3 | D9: Tawiran Bridge | E9: Tawiran, Obando, Bulacan | F9: 1.4 | G9: 1.92 | H9: 2.52 | I9: 3.01 | J9: 4.35 | K9: 5.45 | L9: 4.03 | M9: 5.1 | N9: 4.21 | O9: 5.65 | P9: 4.15 | Q9: 3.53 | R9: =IFERROR(AVERAGE(F9:Q9), 0) -> 3.7766667 | S9: 5 | T9: OBN_3 | AC9: PARAMETERS
B10: BOD (mg/L) | C10: 1 | D10: Polo Bridge | E10: Polo, Valenzuela City, Metro Manila | F10: 13 | G10: 6 | H10: 36 | I10: 19 | J10: 9 | K10: 18 | L10: 13 | M10: 20 | N10: 21 | O10: 5 | P10: 21 | Q10: 14 | R10: =IFERROR(AVERAGE(F10:Q10), 0) -> 16.25 | S10: 7 | T10: OBN_1 | X10: Province / Municipality | Y10: Waterbody | Z10: Class | AA10: No. of Station | AB10: Name of Station | AC10: DO | AD10: BOD | AE10: TSS | AF10: pH | AG10: TEMP | AH10: COLOR | AI10: FECAL COLIFORM | AJ10: NITRATES | AK10: PHOSPHATES | AL10: CHLORIDES
B11: BOD (mg/L) | C11: 2 | D11: Fishport Near Public Market | E11: Paliwas, Obando, Bulacan | F11: 11 | G11: 16 | H11: 22 | I11: 17 | J11: 23 | K11: 16 | L11: 33 | M11: 27 | N11: 92 | O11: 13 | P11: 25 | Q11: 36 | R11: =IFERROR(AVERAGE(F11:Q11), 0) -> 27.583333 | S11: 7 | T11: OBN_2 | X11: OBANDO, BULACAN | Y11: OBANDO RIVER | Z11: C | AA11: 1 | AB11: Tawiran Bridge | AC11: =AVERAGE(F7:K7) -> 5.445 | AD11: =AVERAGE(F10:K10) -> 16.833333 | AE11: =AVERAGE(F13:K13) -> 18.416667 | AF11: =AVERAGE(F16:K16) -> 7.23 | AG11: =AVERAGE(F19:K19) -> 28.578333 | AH11: =AVERAGE(F22:K22) -> 18.333333 | AI11: =GEOMEAN(F25:K25) -> 142747 | AJ11: =AVERAGE(F28:K28) -> 0.59933333 | AK11: =AVERAGE(F31:K31) -> 0.67766667 | AL11: =AVERAGE(F34:K34) -> 155.33333
B12: BOD (mg/L) | C12: 3 | D12: Tawiran Bridge | E12: Tawiran, Obando, Bulacan | F12: 8 | G12: 12 | H12: 6 | I12: 7 | J12: 6 | K12: 20 | L12: 7 | M12: 6 | N12: 8 | O12: 11 | P12: 6 | Q12: 12 | R12: =IFERROR(AVERAGE(F12:Q12), 0) -> 9.0833333 | S12: 7 | T12: OBN_3 | AA12: 2 | AB12: Fishport Near Public Market | AC12: =AVERAGE(F8:K8) -> 2.3616667 | AD12: =AVERAGE(F11:K11) -> 17.5 | AE12: =AVERAGE(F14:K14) -> 47 | AF12: =AVERAGE(F17:K17) -> 7.055 | AG12: =AVERAGE(F20:K20) -> 28.5 | AH12: =AVERAGE(F23:K23) -> 13.333333 | AI12: =GEOMEAN(F26:K26) -> 102963.71 | AJ12: =AVERAGE(F29:K29) -> 0.4925 | AK12: =AVERAGE(F32:K32) -> 0.57916667 | AL12: =AVERAGE(F35:K35) -> 2945.3333
B13: TSS (mg/L) | C13: 1 | D13: Polo Bridge | E13: Polo, Valenzuela City, Metro Manila | F13: 22 | G13: 2.5 | H13: 35 | I13: 13 | J13: 25 | K13: 13 | L13: 49 | M13: 77 | N13: 15 | O13: 26 | P13: 26 | Q13: 42 | R13: =IFERROR(AVERAGE(F13:Q13), 0) -> 28.791667 | S13: 80 | T13: OBN_1 | AA13: 3 | AB13: Polo Bridge | AC13: =AVERAGE(F9:K9) -> 3.1083333 | AD13: =AVERAGE(F12:K12) -> 9.8333333 | AE13: =AVERAGE(F15:K15) -> 48.5 | AF13: =AVERAGE(F18:K18) -> 7.035 | AG13: =AVERAGE(F21:K21) -> 28.516667 | AH13: =AVERAGE(F24:K24) -> 10.833333 | AI13: =GEOMEAN(F27:K27) -> 72670.058 | AJ13: =AVERAGE(F30:K30) -> 0.4735 | AK13: =AVERAGE(F33:K33) -> 0.41883333 | AL13: =AVERAGE(F36:K36) -> 2506.6667
B14: TSS (mg/L) | C14: 2 | D14: Fishport Near Public Market | E14: Paliwas, Obando, Bulacan | F14: 15 | G14: 27 | H14: 47 | I14: 16 | J14: 127 | K14: 50 | L14: 57 | M14: 72 | N14: 19 | O14: 33 | P14: 33 | Q14: 68 | R14: =IFERROR(AVERAGE(F14:Q14), 0) -> 47 | S14: 80 | T14: OBN_2
B15: TSS (mg/L) | C15: 3 | D15: Tawiran Bridge | E15: Tawiran, Obando, Bulacan | F15: 31 | G15: 30 | H15: 89 | I15: 20 | J15: 74 | K15: 47 | L15: 51 | M15: 78 | N15: 16 | O15: 32 | P15: 22 | Q15: 33 | R15: =IFERROR(AVERAGE(F15:Q15), 0) -> 43.583333 | S15: 80 | T15: OBN_3 | X15: AVERAGE | AC15: =AVERAGE(AC11:AC13) -> 3.6383333 | AD15: =AVERAGE(AD11:AD13) -> 14.722222 | AE15: =AVERAGE(AE11:AE13) -> 37.972222 | AF15: =AVERAGE(AF11:AF13) -> 7.1066667 | AG15: =AVERAGE(AG11:AG13) -> 28.531667 | AH15: =AVERAGE(AH11:AH13) -> 14.166667 | AI15: =AVERAGE(AI11:AI13) -> 106126.92 | AJ15: =AVERAGE(AJ11:AJ13) -> 0.52177778 | ... AL15: =AVERAGE(AL11:AL13) -> 1869.1111
B16: pH | C16: 1 | D16: Polo Bridge | E16: Polo, Valenzuela City, Metro Manila | F16: 7.1 | G16: 7.3 | H16: 7.5 | I16: 7.18 | J16: 7.3 | K16: 7 | L16: 7.18 | M16: 7.21 | N16: 7.75 | O16: 7.85 | P16: 7.1 | Q16: 7.59 | R16: =IFERROR(AVERAGE(F16:Q16), 0) -> 7.3383333 | S16: 6.5-9.0 | T16: OBN_1 | X16: MINIMUM | AC16: =MIN(AC11:AC13) -> 2.3616667 | AD16: =MIN(AD11:AD13) -> 9.8333333 | AE16: =MIN(AE11:AE13) -> 18.416667 | AF16: =MIN(AF11:AF13) -> 7.035 | AG16: =MIN(AG11:AG13) -> 28.5 | AH16: =MIN(AH11:AH13) -> 10.833333 | AI16: =MIN(AI11:AI13) -> 72670.058 | AJ16: =MIN(AJ11:AJ13) -> 0.4735 | ... AL16: =MIN(AL11:AL13) -> 155.33333
B17: pH | C17: 2 | D17: Fishport Near Public Market | E17: Paliwas, Obando, Bulacan | F17: 7 | G17: 7.11 | H17: 7 | I17: 7.01 | J17: 7.21 | K17: 7 | L17: 7.01 | M17: 7.01 | N17: 7.65 | O17: 7.61 | P17: 7.38 | Q17: 7.38 | R17: =IFERROR(AVERAGE(F17:Q17), 0) -> 7.1975 | S17: 6.5-9.0 | T17: OBN_2 | X17: MAXIMUM | AC17: =MAX(AC11:AC13) -> 5.445 | AD17: =MAX(AD11:AD13) -> 17.5 | AE17: =MAX(AE11:AE13) -> 48.5 | AF17: =MAX(AF11:AF13) -> 7.23 | AG17: =MAX(AG11:AG13) -> 28.578333 | AH17: =MAX(AH11:AH13) -> 18.333333 | AI17: =MAX(AI11:AI13) -> 142747 | AJ17: =MAX(AJ11:AJ13) -> 0.59933333 | ... AL17: =MAX(AL11:AL13) -> 2945.3333
B18: pH | C18: 3 | D18: Tawiran Bridge | E18: Tawiran, Obando, Bulacan | F18: 6.9 | G18: 7.02 | H18: 6.98 | I18: 7.12 | J18: 7.19 | K18: 7 | L18: 7.15 | M18: 7.18 | N18: 7.75 | O18: 7.78 | P18: 7.35 | Q18: 7.63 | R18: =IFERROR(AVERAGE(F18:Q18), 0) -> 7.2541667 | S18: 6.5-9.0 | T18: OBN_3 | X18: STANDARD | AC18: 5 mg/L | AD18: 7 mg/L | AE18: 80 mg/L | AF18: 6.5-9.0 | AG18: 25-31 °C | AH18: 75 TCU | AI18: 200 MPN/100 L | AJ18: 7 mg/L | AK18: 0.025 mg/L | AL18: 350 mg/L
B19: Temp. (°C) | C19: 1 | D19: Polo Bridge | E19: Polo, Valenzuela City, Metro Manila | F19: 27.3 | G19: 27.3 | H19: 28.9 | I19: 28.7 | J19: 29.4 | K19: 29.87 | L19: 30.1 | M19: 28.9 | N19: 29.8 | O19: 31.1 | P19: 29.1 | Q19: 29.1 | R19: =IFERROR(AVERAGE(F19:Q19), 0) -> 29.130833 | S19: 25-31 | T19: OBN_1
B20: Temp. (°C) | C20: 2 | D20: Fishport Near Public Market | E20: Paliwas, Obando, Bulacan | F20: 27.1 | G20: 26.9 | H20: 28.9 | I20: 29.1 | J20: 29.3 | K20: 29.7 | L20: 29.8 | M20: 29.1 | N20: 29.4 | O20: 31.1 | P20: 29.1 | Q20: 29.1 | R20: =IFERROR(AVERAGE(F20:Q20), 0) -> 29.05 | S20: 25-31 | T20: OBN_2
B21: Temp. (°C) | C21: 3 | D21: Tawiran Bridge | E21: Tawiran, Obando, Bulacan | F21: 27 | G21: 27.3 | H21: 29.1 | I21: 29.2 | J21: 29.1 | K21: 29.4 | L21: 29.7 | M21: 29.8 | N21: 30 | O21: 31.4 | P21: 29.1 | Q21: 29.2 | R21: =IFERROR(AVERAGE(F21:Q21), 0) -> 29.191667 | S21: 25-31 | T21: OBN_3 | X21: Water Quality Statistical Report
B22: Color (TCU) | C22: 1 | D22: Polo Bridge | E22: Polo, Valenzuela City, Metro Manila | F22: 20 | G22: 15 | H22: 15 | I22: 10 | J22: 20 | K22: 30 | L22: 30 | M22: 25 | N22: 25 | O22: 15 | P22: 25 | Q22: 20 | R22: =IFERROR(AVERAGE(F22:Q22), 0) -> 20.833333 | S22: 75 | T22: OBN_1 | X22: Annual 2025
B23: Color (TCU) | C23: 2 | D23: Fishport Near Public Market | E23: Paliwas, Obando, Bulacan | F23: 20 | G23: 10 | H23: 10 | I23: 10 | J23: 15 | K23: 15 | L23: 15 | M23: 15 | N23: 15 | O23: 15 | P23: 15 | Q23: 15 | R23: =IFERROR(AVERAGE(F23:Q23), 0) -> 14.166667 | S23: 75 | T23: OBN_2 | AC23: PARAMETERS
B24: Color (TCU) | C24: 3 | D24: Tawiran Bridge | E24: Tawiran, Obando, Bulacan | F24: 20 | G24: 5 | H24: 5 | I24: 10 | J24: 10 | K24: 15 | L24: 25 | M24: 20 | N24: 15 | O24: 30 | P24: 15 | Q24: 15 | R24: =IFERROR(AVERAGE(F24:Q24), 0) -> 15.416667 | S24: 75 | T24: OBN_3 | X24: Province / Municipality | Y24: Waterbody | Z24: Class | AA24: No. of Station | AB24: Name of Station | AC24: DO | AD24: BOD | AE24: TSS | AF24: pH | AG24: TEMP | AH24: COLOR | AI24: FECAL COLIFORM | AJ24: NITRATES | AK24: PHOSPHATES | AL24: CHLORIDES
B25: Fecal Coliform (MPN/100mL) | C25: 1 | D25: Polo Bridge | E25: Polo, Valenzuela City, Metro Manila | F25: 920000 | G25: 170000 | H25: 24000 | I25: 35000 | J25: 92000 | K25: 700000 | L25: 24000 | M25: 54000 | N25: 350000 | O25: 4600 | P25: 920,.000 | Q25: 160000 | R25: =IFERROR(GEOMEAN(F25:Q25), 0) -> 89142.871 | S25: 200 | T25: OBN_1 | X25: OBANDO, BULACAN | Y25: OBANDO RIVER | Z25: C | AA25: 1 | AB25: Tawiran Bridge | AC25: =R7 -> 5.0091667 | AD25: =R10 -> 16.25 | AE25: =R13 -> 28.791667 | AF25: =R16 -> 7.3383333 | AG25: =R19 -> 29.130833 | AH25: =R22 -> 20.833333 | AI25: =R25 -> 89142.871 | AJ25: =R28 -> 0.40108333 | AK25: =R31 -> 0.64183333 | AL25: =R34 -> 124.66667
B26: Fecal Coliform (MPN/100mL) | C26: 2 | D26: Fishport Near Public Market | E26: Paliwas, Obando, Bulacan | F26: 540000 | G26: 540000 | H26: 35000 | I26: 540000 | J26: 9400 | K26: 23000 | L26: 540000 | M26: 1600000 | N26: 1600000 | O26: 13000 | P26: 1600000 | Q26: 35000 | R26: =IFERROR(GEOMEAN(F26:Q26), 0) -> 180539.61 | S26: 200 | T26: OBN_2 | AA26: 2 | AB26: Fishport Near Public Market | AC26: =R8 -> 2.7683333 | AD26: =R11 -> 27.583333 | AE26: =R14 -> 47 | AF26: =R17 -> 7.1975 | AG26: =R20 -> 29.05 | AH26: =R23 -> 14.166667 | AI26: =R26 -> 180539.61 | AJ26: =R29 -> 0.31 | AK26: =R32 -> 0.66575 | AL26: =R35 -> 1510.9167
B27: Fecal Coliform (MPN/100mL) | C27: 3 | D27: Tawiran Bridge | E27: Tawiran, Obando, Bulacan | F27: 350000 | G27: 920000 | H27: 35000 | I27: 54000 | J27: 2200 | K27: 110000 | L27: 54000 | M27: 350000 | N27: 54000 | O27: 4900 | P27: 920000 | Q27: 54000 | R27: =IFERROR(GEOMEAN(F27:Q27), 0) -> 75906.772 | S27: 200 | T27: OBN_3 | AA27: 3 | AB27: Polo Bridge | AC27: =R9 -> 3.7766667 | AD27: =R12 -> 9.0833333 | AE27: =R15 -> 43.583333 | AF27: =R18 -> 7.2541667 | AG27: =R21 -> 29.191667 | AH27: =R24 -> 15.416667 | AI27: =R27 -> 75906.772 | AJ27: =R30 -> 0.38908333 | AK27: =R33 -> 0.44383333 | AL27: =R36 -> 1291.8333
B28: NO3-N (mg/L) | C28: 1 | D28: Polo Bridge | E28: Polo, Valenzuela City, Metro Manila | F28: 0.418 | G28: 1.583 | H28: 0.828 | I28: 0.344 | J28: 0.101 | K28: 0.322 | L28: 0.332 | M28: 0.25 | N28: 0.173 | O28: 0.323 | P28: 0.09 | Q28: 0.049 | R28: =IFERROR(AVERAGE(F28:Q28), 0) -> 0.40108333 | S28: 7 | T28: OBN_1
B29: NO3-N (mg/L) | C29: 2 | D29: Fishport Near Public Market | E29: Paliwas, Obando, Bulacan | F29: 0.391 | G29: 1.159 | H29: 0.563 | I29: 0.451 | J29: 0.136 | K29: 0.255 | L29: 0.043 | M29: 0.08 | N29: 0.157 | O29: 0.233 | P29: 0.149 | Q29: 0.103 | R29: =IFERROR(AVERAGE(F29:Q29), 0) -> 0.31 | S29: 7 | T29: OBN_2 | X29: AVERAGE | AC29: =AVERAGE(AC25:AC27) -> 3.8513889 | AD29: =AVERAGE(AD25:AD27) -> 17.638889 | AE29: =AVERAGE(AE25:AE27) -> 39.791667 | AF29: =AVERAGE(AF25:AF27) -> 7.2633333 | AG29: =AVERAGE(AG25:AG27) -> 29.124167 | AH29: =AVERAGE(AH25:AH27) -> 16.805556 | AI29: =AVERAGE(AI25:AI27) -> 115196.42 | AJ29: =AVERAGE(AJ25:AJ27) -> 0.36672222 | ... AL29: =AVERAGE(AL25:AL27) -> 975.80556
B30: NO3-N (mg/L) | C30: 3 | D30: Tawiran Bridge | E30: Tawiran, Obando, Bulacan | F30: 0.311 | G30: 1.216 | H30: 0.631 | I30: 0.311 | J30: 0.043 | K30: 0.329 | L30: 0.452 | M30: 0.352 | N30: 0.41 | O30: 0.337 | P30: 0.165 | Q30: 0.112 | R30: =IFERROR(AVERAGE(F30:Q30), 0) -> 0.38908333 | S30: 7 | T30: OBN_3 | X30: MINIMUM | AC30: =MIN(AC25:AC27) -> 2.7683333 | AD30: =MIN(AD25:AD27) -> 9.0833333 | AE30: =MIN(AE25:AE27) -> 28.791667 | AF30: =MIN(AF25:AF27) -> 7.1975 | AG30: =MIN(AG25:AG27) -> 29.05 | AH30: =MIN(AH25:AH27) -> 14.166667 | AI30: =MIN(AI25:AI27) -> 75906.772 | AJ30: =MIN(AJ25:AJ27) -> 0.31 | ... AL30: =MIN(AL25:AL27) -> 124.66667
B31: PO4-P (mg/L) | C31: 1 | D31: Polo Bridge | E31: Polo, Valenzuela City, Metro Manila | F31: 0.647 | G31: 1.077 | H31: 0.514 | I31: 0.628 | J31: 0.458 | K31: 0.742 | L31: 0.321 | M31: 0.774 | N31: 0.782 | O31: 0.496 | P31: 0.817 | Q31: 0.446 | R31: =IFERROR(AVERAGE(F31:Q31), 0) -> 0.64183333 | S31: 0.025 | T31: OBN_1 | X31: MAXIMUM | AC31: =MAX(AC25:AC27) -> 5.0091667 | AD31: =MAX(AD25:AD27) -> 27.583333 | AE31: =MAX(AE25:AE27) -> 47 | AF31: =MAX(AF25:AF27) -> 7.3383333 | AG31: =MAX(AG25:AG27) -> 29.191667 | AH31: =MAX(AH25:AH27) -> 20.833333 | AI31: =MAX(AI25:AI27) -> 180539.61 | AJ31: =MAX(AJ25:AJ27) -> 0.40108333 | ... AL31: =MAX(AL25:AL27) -> 1510.9167
B32: PO4-P (mg/L) | C32: 2 | D32: Fishport Near Public Market | E32: Paliwas, Obando, Bulacan | F32: 0.62 | G32: 0.676 | H32: 0.6 | I32: 0.293 | J32: 0.761 | K32: 0.525 | L32: 0.466 | M32: 0.75 | N32: 0.786 | O32: 0.752 | P32: 0.856 | Q32: 0.904 | R32: =IFERROR(AVERAGE(F32:Q32), 0) -> 0.66575 | S32: 0.025 | T32: OBN_2 | X32: STANDARD | AC32: 5 mg/L | AD32: 7 mg/L | AE32: 80 mg/L | AF32: 6.5-9.0 | AG32: 25-31 °C | AH32: 75 TCU | AI32: 200 MPN/100 L | AJ32: 7 mg/L | AK32: 0.025 mg/L | AL32: 350 mg/L
B33: PO4-P (mg/L) | C33: 3 | D33: Tawiran Bridge | E33: Tawiran, Obando, Bulacan | F33: 0.823 | G33: 0.011 | H33: 0.377 | I33: 0.362 | J33: 0.433 | K33: 0.507 | L33: 0.236 | M33: 0.31 | N33: 0.494 | O33: 0.485 | P33: 0.626 | Q33: 0.662 | R33: =IFERROR(AVERAGE(F33:Q33), 0) -> 0.44383333 | S33: 0.025 | T33: OBN_3
B34: Cl- (mg/L) | C34: 1 | D34: Polo Bridge | E34: Polo, Valenzuela City, Metro Manila | F34: 92 | G34: 231 | H34: 107 | I34: 113 | J34: 172 | K34: 217 | L34: 133 | M34: 122 | N34: 90 | O34: 31 | P34: 94 | Q34: 94 | R34: =IFERROR(AVERAGE(F34:Q34), 0) -> 124.66667 | S34: 350 | T34: OBN_1
B35: Cl- (mg/L) | C35: 2 | D35: Fishport Near Public Market | E35: Paliwas, Obando, Bulacan | F35: 165 | G35: 337 | H35: 16895 | I35: 43 | J35: 65 | K35: 167 | L35: 48 | M35: 125 | N35: 202 | O35: 29 | P35: 29 | Q35: 26 | R35: =IFERROR(AVERAGE(F35:Q35), 0) -> 1510.9167 | S35: 350 | T35: OBN_2
B36: Cl- (mg/L) | C36: 3 | D36: Tawiran Bridge | E36: Tawiran, Obando, Bulacan | F36: 199 | G36: 415 | H36: 13996 | I36: 33 | J36: 67 | K36: 330 | L36: 37 | M36: 53 | N36: 202 | O36: 24 | P36: 114 | Q36: 32 | R36: =IFERROR(AVERAGE(F36:Q36), 0) -> 1291.8333 | S36: 350 | T36: OBN_3
B37: Oil & Grease | C37: 1 | D37: Tawiran Bridge | E37: Polo, Valenzuela City, Metro Manila | F37: 1.1 | G37: - | H37: - | I37: - | J37: - | K37: 0.08 | L37: 1.6 | M37: - | N37: - | O37: - | P37: - | Q37: - | R37: =IFERROR(AVERAGE(F37:Q37), 0) -> 0.92666667 | S37: 3 | T37: OBN_1
B38: Cl- (mg/L) | C38: 2 | D38: Fishport Near Public Market | E38: Paliwas, Obando, Bulacan | F38: 21.4 | G38: - | H38: - | I38: - | J38: - | K38: 1.1 | L38: 3.7 | M38: - | N38: - | O38: - | P38: - | Q38: - | R38: =IFERROR(AVERAGE(F38:Q38), 0) -> 8.7333333 | S38: 3 | T38: OBN_2
B39: Cl- (mg/L) | C39: 3 | D39: Polo Bridge | E39: Tawiran, Obando, Bulacan | F39: 1.4 | G39: - | H39: - | I39: - | J39: - | K39: 1.7 | L39: 0.8 | M39: - | N39: - | O39: - | P39: - | Q39: - | R39: =IFERROR(AVERAGE(F39:Q39), 0) -> 1.3 | S39: 3 | T39: OBN_3
B40: Observation | C40: 1 | D40: Polo Bridge | E40: Polo, Valenzuela City, Metro Manila | F40: near residential area/ commercial area, presence of few floating solid waste | G40: Residential/ commercial area and presence of few floating of solid waste | H40: Residential/ commercial area, few floating of soliid waste | I40: Residential/ commercial area, public market, few solid waste afloat | J40: Commercial/ residential area, presence of few floating of solid wastes | K40: On-going construction of bridge, dredging vessel anchored near sampling station, near fishpond & few residential houses | L40: residential/ commercial area, presence of few solid waste afloat | M40: on-going construction of bridge, dredging ship docked near the station, presence of few floating of solid waste and hyacinth | N40: visible of fishing boat/heavy equipment,on going construction of bridge,presence of hyacinth/solid waste | O40: on-gong construction of bridge, visible of dredging equipment and heavy equipment, presence of few rotten hyacinth and solid waste | P40: visible of solid waste, hyacinth and bubbles, stagnant water | Q40: Presence of rotting organic matter/ near residential and commercial area | T40: OBN_1
...

Sheet BOCAUE RIVER
C1: SUMMARY REPORT OF WATER QUALITY MONITORING DATA
C2: SUBMITTED BY THE REGIONAL OFFICES
C3: CY 2025
C4: BOCAUE RIVER
C5: CLASS C ( 3 STATIONS )
A6: Region | B6: Parameter | C6: Stn. No. | D6: Stn. ID | E6: Address | F6: January | G6: February | H6: March | I6: April | J6: May | K6: June | L6: July | M6: August | N6: September | O6: October | P6: November | Q6: December | R6: Average/Geomean | S6: WQG | T6: Code
A7: III | B7: DO (mg/L) | C7: 1 | D7: Expressway Bridge | E7: Brgy. Turo, Bocaue, Bulacan | F7: 1.9 | G7: 1.59 | H7: 1.9 | I7: 4.56 | J7: 2.59 | K7: 3.25 | L7: 4.95 | M7: 4.1 | N7: 4.7 | O7: 4.44 | P7: 4.71 | Q7: 3.1 | R7: =IFERROR(AVERAGE(F7:Q7), 0) -> 3.4825 | S7: 5 | T7: BOC_1 | X7: Water Quality Statistical Report
B8: DO (mg/L) | C8: 2 | D8: McArthur Bridge | E8: Brgy. Biñang 2nd, Bocaue, Bul. | F8: 1.9 | G8: 1.57 | H8: 2.7 | I8: 4.53 | J8: 2.8 | K8: 3.62 | L8: 5.01 | M8: 4.05 | N8: 4.8 | O8: 4.59 | P8: 4.45 | Q8: 3.25 | R8: =IFERROR(AVERAGE(F8:Q8), 0) -> 3.6058333 | S8: 5 | T8: BOC_2 | X8: 1st Semi-Annual 2025
B9: DO (mg/L) | C9: 3 | D9: Bridge near public Market (UBVAS) | E9: Brgy. Biñang 2nd, Bocaue, Bul. | F9: 1.9 | G9: 1.59 | H9: 2.53 | I9: 4.54 | J9: 2.67 | K9: 4.59 | L9: 5.61 | M9: 4.23 | N9: 4.2 | O9: 4.65 | P9: 4.53 | Q9: 3.05 | R9: =IFERROR(AVERAGE(F9:Q9), 0) -> 3.6741667 | S9: 5 | T9: BOC_3 | AC9: PARAMETERS
B10: BOD (mg/L) | C10: 1 | D10: Expressway Bridge | E10: Brgy. Turo, Bocaue, Bulacan | F10: 13 | G10: 10 | H10: 10 | I10: 11 | J10: 7 | K10: 9 | L10: 2 | M10: 6 | N10: 9 | O10: 7 | P10: 4 | Q10: 9 | R10: =IFERROR(AVERAGE(F10:Q10), 0) -> 8.0833333 | S10: 7 | T10: BOC_1 | X10: Province / Municipality | Y10: Waterbody | Z10: Class | AA10: No. of Station | AB10: Name of Station | AC10: DO | AD10: BOD | AE10: TSS | AF10: pH | AG10: TEMP | AH10: COLOR | AI10: FECAL COLIFORM | AJ10: NITRATES | AK10: PHOSPHATES | AL10: CHLORIDES
B11: BOD (mg/L) | C11: 2 | D11: McArthur Bridge | E11: Brgy. Biñang 2nd, Bocaue, Bul. | F11: 8 | G11: 11 | H11: 10 | I11: 14 | J11: 7 | K11: 7 | L11: 2 | M11: 6 | N11: 7 | O11: 6 | P11: 4 | Q11: 10 | R11: =IFERROR(AVERAGE(F11:Q11), 0) -> 7.6666667 | S11: 7 | T11: BOC_2 | X11: BOCAUE, BULACAN | Y11: BOCAUE RIVER | Z11: C | AA11: 1 | AB11: Bridge near public Market (UBVAS) | AC11: =AVERAGE(F7:K7) -> 2.6316667 | AD11: =AVERAGE(F10:K10) -> 10 | AE11: =AVERAGE(F13:K13) -> 18 | AF11: =AVERAGE(F16:K16) -> 7.1083333 | AG11: =AVERAGE(F19:K19) -> 28.833333 | AH11: =AVERAGE(F22:K22) -> 26.666667 | AI11: =GEOMEAN(F25:K25) -> 487437.15 | AJ11: =AVERAGE(F28:K28) -> 0.80033333 | AK11: =AVERAGE(F31:K31) -> 0.77133333 | AL11: =AVERAGE(F34:K34) -> 214.16667
B12: BOD (mg/L) | C12: 3 | D12: Bridge near public Market (UBVAS) | E12: Brgy. Biñang 2nd, Bocaue, Bul. | F12: 8 | G12: 14 | H12: 11 | I12: 11 | J12: 6 | K12: 9 | L12: 2 | M12: 7 | N12: 9 | O12: 7 | P12: 5 | Q12: 8 | R12: =IFERROR(AVERAGE(F12:Q12), 0) -> 8.0833333 | S12: 7 | T12: BOC_3 | AA12: 2 | AB12: McArthur Bridge | AC12: =AVERAGE(F8:K8) -> 2.8533333 | AD12: =AVERAGE(F11:K11) -> 9.5 | AE12: =AVERAGE(F14:K14) -> 17.166667 | AF12: =AVERAGE(F17:K17) -> 7.105 | AG12: =AVERAGE(F20:K20) -> 28.65 | AH12: =AVERAGE(F23:K23) -> 26.666667 | AI12: =GEOMEAN(F26:K26) -> 517260.25 | AJ12: =AVERAGE(F29:K29) -> 0.89383333 | AK12: =AVERAGE(F32:K32) -> 0.765 | AL12: =AVERAGE(F35:K35) -> 184.66667
B13: TSS (mg/L) | C13: 1 | D13: Expressway Bridge | E13: Brgy. Turo, Bocaue, Bulacan | F13: 11 | G13: 15 | H13: 13 | I13: 13 | J13: 17 | K13: 39 | L13: 40 | M13: 8 | N13: 37 | O13: 43 | P13: 32 | Q13: 53 | R13: =IFERROR(AVERAGE(F13:Q13), 0) -> 26.75 | S13: 80 | T13: BOC_1 | AA13: 3 | AB13: Expressway Bridge | AC13: =AVERAGE(F9:K9) -> 2.97 | AD13: =AVERAGE(F12:K12) -> 9.8333333 | AE13: =AVERAGE(F15:K15) -> 19.166667 | AF13: =AVERAGE(F18:K18) -> 7.1483333 | AG13: =AVERAGE(F21:K21) -> 28.433333 | AH13: =AVERAGE(F24:K24) -> 26.666667 | AI13: =GEOMEAN(F27:K27) -> 553624.33 | AJ13: =AVERAGE(F30:K30) -> 1.0518333 | AK13: =AVERAGE(F33:K33) -> 0.77616667 | AL13: =AVERAGE(F36:K36) -> 209.83333
B14: TSS (mg/L) | C14: 2 | D14: McArthur Bridge | E14: Brgy. Biñang 2nd, Bocaue, Bul. | F14: 12 | G14: 11 | H14: 13 | I14: 15 | J14: 9 | K14: 43 | L14: 63 | M14: 12 | N14: 31 | O14: 33 | P14: 39 | Q14: 56 | R14: =IFERROR(AVERAGE(F14:Q14), 0) -> 28.083333 | S14: 80 | T14: BOC_2
B15: TSS (mg/L) | C15: 3 | D15: Bridge near public Market (UBVAS) | E15: Brgy. Biñang 2nd, Bocaue, Bul. | F15: 10 | G15: 9 | H15: 12 | I15: 13 | J15: 21 | K15: 50 | L15: 29 | M15: 9 | N15: 45 | O15: 29 | P15: 31 | Q15: 55 | R15: =IFERROR(AVERAGE(F15:Q15), 0) -> 26.083333 | S15: 80 | T15: BOC_3 | X15: AVERAGE | AC15: =AVERAGE(AC11:AC13) -> 2.8183333 | AD15: =AVERAGE(AD11:AD13) -> 9.7777778 | AE15: =AVERAGE(AE11:AE13) -> 18.111111 | AF15: =AVERAGE(AF11:AF13) -> 7.1205556 | AG15: =AVERAGE(AG11:AG13) -> 28.638889 | AH15: =AVERAGE(AH11:AH13) -> 26.666667 | AI15: =AVERAGE(AI11:AI13) -> 519440.58 | AJ15: =AVERAGE(AJ11:AJ13) -> 0.91533333 | ... AL15: =AVERAGE(AL11:AL13) -> 202.88889
B16: pH | C16: 1 | D16: Expressway Bridge | E16: Brgy. Turo, Bocaue, Bulacan | F16: 7.1 | G16: 7 | H16: 7.01 | I16: 7.25 | J16: 7.28 | K16: 7.01 | L16: 7.12 | M16: 7.05 | N16: 8.18 | O16: 7.81 | P16: 7.5 | Q16: 7.58 | R16: =IFERROR(AVERAGE(F16:Q16), 0) -> 7.3241667 | S16: 6.5-9.0 | T16: BOC_1 | X16: MINIMUM | AC16: =MIN(AC11:AC13) -> 2.6316667 | AD16: =MIN(AD11:AD13) -> 9.5 | AE16: =MIN(AE11:AE13) -> 17.166667 | AF16: =MIN(AF11:AF13) -> 7.105 | AG16: =MIN(AG11:AG13) -> 28.433333 | AH16: =MIN(AH11:AH13) -> 26.666667 | AI16: =MIN(AI11:AI13) -> 487437.15 | AJ16: =MIN(AJ11:AJ13) -> 0.80033333 | ... AL16: =MIN(AL11:AL13) -> 184.66667
B17: pH | C17: 2 | D17: McArthur Bridge | E17: Brgy. Biñang 2nd, Bocaue, Bul. | F17: 7.1 | G17: 7.02 | H17: 7.03 | I17: 7.2 | J17: 7.17 | K17: 7.11 | L17: 7.1 | M17: 7.05 | N17: 7.85 | O17: 7.77 | P17: 7.48 | Q17: 7.61 | R17: =IFERROR(AVERAGE(F17:Q17), 0) -> 7.2908333 | S17: 6.5-9.0 | T17: BOC_2 | X17: MAXIMUM | AC17: =MAX(AC11:AC13) -> 2.97 | AD17: =MAX(AD11:AD13) -> 10 | AE17: =MAX(AE11:AE13) -> 19.166667 | AF17: =MAX(AF11:AF13) -> 7.1483333 | AG17: =MAX(AG11:AG13) -> 28.833333 | AH17: =MAX(AH11:AH13) -> 26.666667 | AI17: =MAX(AI11:AI13) -> 553624.33 | AJ17: =MAX(AJ11:AJ13) -> 1.0518333 | ... AL17: =MAX(AL11:AL13) -> 214.16667
B18: pH | C18: 3 | D18: Bridge near public Market (UBVAS) | E18: Brgy. Biñang 2nd, Bocaue, Bul. | F18: 7 | G18: 6.99 | H18: 7.11 | I18: 7.28 | J18: 7.22 | K18: 7.29 | L18: 7.12 | M18: 7.08 | N18: 7.81 | O18: 7.83 | P18: 7.51 | Q18: 7.53 | R18: =IFERROR(AVERAGE(F18:Q18), 0) -> 7.3141667 | S18: 6.5-9.0 | T18: BOC_3 | X18: STANDARD | AC18: 5 mg/L | AD18: 7 mg/L | AE18: 80 mg/L | AF18: 6.5-9.0 | AG18: 25-31 °C | AH18: 75 TCU | AI18: 200 MPN/100 L | AJ18: 7 mg/L | AK18: 0.025 mg/L | AL18: 350 mg/L
B19: Temp. (°C) | C19: 1 | D19: Expressway Bridge | E19: Brgy. Turo, Bocaue, Bulacan | F19: 27.4 | G19: 26.1 | H19: 28.8 | I19: 31.1 | J19: 31.1 | K19: 28.5 | L19: 28.8 | M19: 29.9 | N19: 30.1 | O19: 27.2 | P19: 28.4 | Q19: 26.8 | R19: =IFERROR(AVERAGE(F19:Q19), 0) -> 28.683333 | S19: 25-31 | T19: BOC_1
B20: Temp. (°C) | C20: 2 | D20: McArthur Bridge | E20: Brgy. Biñang 2nd, Bocaue, Bul. | F20: 27.4 | G20: 26.2 | H20: 27.7 | I20: 31 | J20: 31.5 | K20: 28.1 | L20: 28.2 | M20: 30 | N20: 29.2 | O20: 27.1 | P20: 28.4 | Q20: 26.1 | R20: =IFERROR(AVERAGE(F20:Q20), 0) -> 28.408333 | S20: 25-31 | T20: BOC_2
B21: Temp. (°C) | C21: 3 | D21: Bridge near public Market (UBVAS) | E21: Brgy. Biñang 2nd, Bocaue, Bul. | F21: 27.3 | G21: 26.1 | H21: 28.1 | I21: 30.8 | J21: 31.5 | K21: 26.8 | L21: 27.1 | M21: 29.3 | N21: 29.1 | O21: 27.1 | P21: 28.2 | Q21: 26.1 | R21: =IFERROR(AVERAGE(F21:Q21), 0) -> 28.125 | S21: 25-31 | T21: BOC_3 | X21: Water Quality Statistical Report
B22: Color (TCU) | C22: 1 | D22: Expressway Bridge | E22: Brgy. Turo, Bocaue, Bulacan | F22: 25 | G22: 25 | H22: 25 | I22: 25 | J22: 30 | K22: 30 | L22: 30 | M22: 20 | N22: 10 | O22: 15 | P22: 15 | Q22: 15 | R22: =IFERROR(AVERAGE(F22:Q22), 0) -> 22.083333 | S22: 75 | T22: BOC_1 | X22: Annual 2025
B23: Color (TCU) | C23: 2 | D23: McArthur Bridge | E23: Brgy. Biñang 2nd, Bocaue, Bul. | F23: 25 | G23: 25 | H23: 25 | I23: 25 | J23: 30 | K23: 30 | L23: 30 | M23: 20 | N23: 10 | O23: 15 | P23: 10 | Q23: 15 | R23: =IFERROR(AVERAGE(F23:Q23), 0) -> 21.666667 | S23: 75 | T23: BOC_2 | AC23: PARAMETERS
